Workbook

Sheet 00_Cover
A1: InterGlobe Aviation Equity Research Model
A2: Historical analysis, driver-based forecast and discounted cash flow valuation
A4: Purpose
A5: Airline operating analysis, financial forecasting, unlevered cash flow, WACC and DCF valuation.
A7: Key Outputs
A8: FY2026A revenue | B8: INR crore | C8: ='07_Income_Statement'!E11 -> 84961.9
A9: FY2031E revenue | B9: INR crore | C9: ='07_Income_Statement'!J11 -> 153031.25
A10: FY2031E EBIT margin | B10: % | C10: ='07_Income_Statement'!J25 -> 0.062176512
A11: FY2031E unlevered free cash flow | B11: INR crore | C11: ='09_Cash_Flow'!J16 -> 3839.6436
A12: Base-case implied value per share | B12: INR per share | C12: ='11_DCF'!C33 -> 0
A13: Market price (07-Sep-2026) | B13: INR per share | C13: ='12_Reverse_DCF'!C7 -> 5001
A17: Model Flow
A18: Historical financials and operating KPIs
A19: Industry context and historical analysis
A20: Operating drivers and income statement
A21: Fleet, lease, working-capital and finance schedules
A22: Unlevered free cash flow
A23: Operating scenarios, DCF and reverse DCF
A26: Workbook Sections
A27: Sources and raw data | B27: Sheets 01 to 04
A28: Historical analysis | B28: Sheet 05
A29: Forecast model | B29: Sheets 06 to 08
A30: Cash flow and valuation | B30: Sheets 09 to 12
A32: Color Convention
A33: Blue font | B33: Editable assumptions and hardcoded inputs
A34: Green font | B34: Links to other worksheets
A35: Black font | B35: Formulas and calculations
A36: Scope | B36: Independent equity research model; not investment advice.

Sheet 01_Sources
A1: Sources and References
A2: Company reports used for the historical financial statements
A3: FY2016 is standalone under previous GAAP; FY2017 onward is consolidated under Ind AS.
A4: Annual Reports
A5: Period | B5: Source document | C5: Reporting basis | D5: File name
A6: FY2016 | B6: Annual Report FY2016 | C6: Standalone | previous GAAP | D6: InterGlobe_Aviation_Annual_Report_FY2016.pdf
A7: FY2017 | B7: Annual Report FY2017 | C7: Consolidated | Ind AS | D7: InterGlobe_Aviation_Annual_Report_FY2017.pdf
A8: FY2018 | B8: Annual Report FY2018 | C8: Consolidated | Ind AS | D8: InterGlobe_Aviation_Annual_Report_FY2018.pdf
A9: FY2019 | B9: Annual Report FY2019 | C9: Consolidated | Ind AS | D9: InterGlobe_Aviation_Annual_Report_FY2019.pdf
A10: FY2020 | B10: Annual Report FY2020 | C10: Consolidated | Ind AS | D10: InterGlobe_Aviation_Annual_Report_FY2020.pdf
A11: FY2021 | B11: Annual Report FY2021 | C11: Consolidated | Ind AS | D11: InterGlobe_Aviation_Annual_Report_FY2021.pdf
A12: FY2022 | B12: Annual Report FY2022 | C12: Consolidated | Ind AS | D12: InterGlobe_Aviation_Annual_Report_FY2022.pdf
A13: FY2023 | B13: Annual Report FY2023 | C13: Consolidated | Ind AS | D13: InterGlobe_Aviation_Annual_Report_FY2023.pdf
A14: FY2024 | B14: Annual Report FY2024 | C14: Consolidated | Ind AS | D14: InterGlobe_Aviation_Annual_Report_FY2024.pdf
A15: FY2025 | B15: Annual Report FY2025 | C15: Consolidated | Ind AS | D15: InterGlobe_Aviation_Annual_Report_FY2025.pdf
A16: FY2026 | B16: Annual Report FY2026 | C16: Consolidated | Ind AS | D16: InterGlobe_Aviation_Annual_Report_FY2026.pdf
A17: Market Data
A18: 46272 | B18: Screener - InterGlobe Aviation | C18: Market price reference | D18: Screener company page

Sheet 02_Raw_Financials
A1: Historical Financial Statements
A2: InterGlobe Aviation Limited | FY2016-FY2026 | INR crore unless stated
A3: FY2016 is standalone under previous GAAP; FY2017 onward is consolidated under Ind AS. Ind AS 116 was adopted in FY2020.
A5: Metric | B5: Unit | C5: FY2016 | D5: FY2017 | E5: FY2018 | F5: FY2019 | G5: FY2020 | H5: FY2021 | I5: FY2022 | J5: FY2023 | K5: FY2024 | L5: FY2025 | M5: FY2026
A6: Source document | C6: Annual Report FY2016 | D6: Annual Report FY2017 | E6: Annual Report FY2018 | F6: Annual Report FY2019 | G6: Annual Report FY2020 | H6: Annual Report FY2021 | I6: Annual Report FY2022 | J6: Annual Report FY2023 | K6: Annual Report FY2024 | L6: Annual Report FY2025 | M6: FY2026 Audited Consolidated Results
A7: Income Statement
A8: Revenue from operations | B8: INR crore | C8: 16139.909 | D8: 18580.5 | E8: 23020.887 | F8: 28496.772 | G8: 35756.001 | H8: 14640.631 | I8: 25930.927 | J8: 54446.453 | K8: 68904.342 | L8: 80802.9 | M8: 84961.9
A9: Other income | B9: INR crore | C9: 461.393 | D9: 789.07 | E9: 946.856 | F9: 1324.598 | G9: 1535.509 | H9: 1036.964 | I9: 725.598 | J9: 1434.965 | K9: 2326.821 | L9: 3295.3 | M9: 4551.5
A10: Total income | B10: INR crore | C10: =C8+C9 -> 16601.302 | D10: =D8+D9 -> 19369.57 | E10: =E8+E9 -> 23967.743 | F10: =F8+F9 -> 29821.37 | G10: =G8+G9 -> 37291.51 | H10: =H8+H9 -> 15677.595 | I10: =I8+I9 -> 26656.525 | J10: =J8+J9 -> 55881.418 | ... M10: =M8+M9 -> 89513.4
A11: Aircraft fuel expense | B11: INR crore | C11: 4779.324 | D11: 6341.513 | E11: 7760.136 | F11: 11942.793 | G11: 12453.794 | H11: 3831.277 | I11: 9695.236 | J11: 23646.017 | K11: 23904.578 | L11: 26197.3 | M11: 25389.2
A12: Aircraft and engine rentals | B12: INR crore | C12: 2612.152 | D12: 3125.373 | E12: 3610.199 | F12: 4999.449 | G12: 496.657 | H12: 280.457 | I12: 311.684 | J12: 325.84 | K12: 1075.195 | L12: 3010.3 | M12: 2084.7
A13: Supplementary rentals and maintenance | B13: INR crore | G13: 5867.237 | H13: 4191.26 | I13: 6089.784 | J13: 8044.96 | K13: 9931.624 | L13: 11218.5 | M13: 12912.1
A14: Airport fees and charges | B14: INR crore | G14: 2911.684 | H14: 1612.884 | I14: 2286.837 | J14: 3646.8 | K14: 4623.943 | L14: 5753.1 | M14: 6548.2
A15: Purchase of stock-in-trade | B15: INR crore | C15: 114.782 | D15: 123.832 | E15: 123.876 | F15: 139.795 | G15: 180.908 | H15: 54.321 | I15: 118.142 | J15: 287.244 | K15: 336.861 | L15: 383.4 | M15: 496.3
A16: Change in inventories | B16: INR crore | C16: -1.132 | D16: -0.294 | E16: 1.265 | F16: -0.655 | G16: -3.053 | H16: 1.161 | I16: -1.677 | J16: -1.244 | K16: 5.41 | L16: -0.2 | M16: -1.4
A17: Employee expense | B17: INR crore | C17: 1789.923 | D17: 2048.19 | E17: 2455.022 | F17: 3210.557 | G17: 4709.959 | H17: 3295.492 | I17: 3486.443 | J17: 4794.752 | K17: 6461.856 | L17: 7472.5 | M17: 8272.2
A18: Foreign exchange loss (net) | B18: INR crore | F18: 467.487 | G18: 1546.189 | H18: -523.026 | I18: 940.838 | J18: 2959.773 | K18: 717.397 | L18: 1617.9 | M18: 8975.7
A19: Other expenses | B19: INR crore | C19: 3839.371 | D19: 4798.624 | E19: 6113.926 | F19: 7940.779 | G19: 3534.004 | H19: 1910.41 | I19: 2456.307 | J19: 4246.961 | K19: 5529.907 | L19: 7091.8 | M19: 8301.5
A20: Depreciation and amortisation | B20: INR crore | C20: 503.079 | D20: 457.253 | E20: 436.877 | F20: 759.58 | G20: 3973.929 | H20: 4699.446 | I20: 5068.6 | J20: 5102.969 | K20: 6425.729 | L20: 8680.2 | M20: 10808.2
A21: Finance costs | B21: INR crore | C21: 134.853 | D21: 330.78 | E21: 339.815 | F21: 508.963 | G21: 1875.871 | H21: 2141.983 | I21: 2358.015 | J21: 3131.731 | K21: 4169.354 | L21: 5080 | M21: 5890.8
A22: Total expenses | B22: INR crore | C22: 13772.352 | D22: 17225.271 | E22: 20841.116 | F22: 29968.748 | G22: 37547.179 | H22: 21495.665 | I22: 32810.209 | J22: 56185.803 | K22: 63181.854 | L22: 76504.8 | M22: 89677.5
A23: Exceptional items | B23: INR crore | M23: 1796.4
A24: Profit before tax | B24: INR crore | C24: 2828.95 | D24: 2144.299 | E24: 3126.627 | F24: -147.378 | G24: -255.669 | H24: -5818.07 | I24: -6153.684 | J24: -304.385 | K24: 8049.309 | L24: 7593.4 | M24: -1960.5
A25: Total tax expense / (credit) | B25: INR crore | C25: 839.23 | D25: 485.152 | E25: 884.303 | F25: -304.625 | G25: -21.991 | H25: -11.643 | I25: 8.161 | J25: 1.404 | K25: -123.159 | L25: 335 | M25: 433.1
A26: Profit after tax | B26: INR crore | C26: 1989.72 | D26: 1659.147 | E26: 2242.324 | F26: 157.247 | G26: -233.678 | H26: -5806.427 | I26: -6161.845 | J26: -305.789 | K26: 8172.468 | L26: 7258.4 | M26: -2393.6
A27: Basic EPS | B27: INR per share | C27: 58.17 | D27: 45.94 | E27: 60.03 | F27: 4.09 | G27: -6.07 | H27: -150.89 | I27: -160.01 | J27: -7.93 | K27: 211.84 | L27: 187.93 | M27: -61.88
A28: Diluted EPS | B28: INR per share | C28: 56.49 | D28: 45.85 | E28: 59.9 | F28: 4.09 | G28: -6.07 | H28: -150.89 | I28: -160.01 | J28: -7.93 | K28: 211.61 | L28: 187.67 | M28: -61.88
A29: Total expense check | B29: INR crore | C29: =SUM(C11:C21)-C22 -> 0 | D29: =SUM(D11:D21)-D22 -> 0 | E29: =SUM(E11:E21)-E22 -> 0 | F29: =SUM(F11:F21)-F22 -> 0 | G29: =SUM(G11:G21)-G22 -> 0 | H29: =SUM(H11:H21)-H22 -> 0 | I29: =SUM(I11:I21)-I22 -> 0 | J29: =SUM(J11:J21)-J22 -> 0 | ... M29: =SUM(M11:M21)-M22 -> 0
A30: P&L check | B30: INR crore | C30: =C10-C22-C23-C24 -> 0 | D30: =D10-D22-D23-D24 -> 0 | E30: =E10-E22-E23-E24 -> 0 | F30: =F10-F22-F23-F24 -> -4.2632564e-12 | G30: =G10-G22-G23-G24 -> 5.5990768e-12 | H30: =H10-H22-H23-H24 -> 0 | I30: =I10-I22-I23-I24 -> 0 | J30: =J10-J22-J23-J24 -> -2.0463631e-12 | ... M30: =M10-M22-M23-M24 -> -5.9117156e-12
A32: Balance Sheet
A33: Property, plant and equipment | B33: INR crore | C33: 4675.515 | D33: 3747.472 | E33: 4534.756 | F33: 5631.554 | G33: 2499.569 | H33: 796.966 | I33: 823.953 | J33: 1111.169 | K33: 1902.912 | L33: 2677.9 | M33: 11087.1
A34: Right-of-use assets | B34: INR crore | C34: 0 | D34: 0 | E34: 0 | F34: 0 | G34: 14246.138 | H34: 17986.171 | I34: 20438.148 | J34: 26536.495 | K34: 34202.308 | L34: 49073.9 | M34: 52054
A35: Capital work-in-progress | B35: INR crore | C35: 23.734 | D35: 23.303 | E35: 29.42 | F35: 22.015 | G35: 129.27 | H35: 66.351 | I35: 119.318 | J35: 0 | K35: 0.143 | L35: 0.7 | M35: 38.7
A36: Intangible assets | B36: INR crore | C36: 19.974 | D36: 46.369 | E36: 44.053 | F36: 30.488 | G36: 33.591 | H36: 33.496 | I36: 21.562 | J36: 10.727 | K36: 48.327 | L36: 29.9 | M36: 16
A37: Intangible assets under development | B37: INR crore | C37: 8.231 | D37: 1.883 | E37: 3.07 | F37: 1.614 | G37: 10.969 | H37: 5.419 | I37: 6.039 | J37: 20.817 | K37: 1.339 | L37: 2.3 | M37: 20.6
A38: Non-current investments | B38: INR crore | C38: 0.025 | D38: 0.018 | E38: 0.017 | F38: 0.015 | G38: 0.075 | H38: 0.083 | I38: 0.012 | J38: 0.068 | K38: 974.839 | L38: 1318.3 | M38: 1931
A39: Non-current loans | B39: INR crore | C39: 1193.062 | D39: 544.026 | E39: 683.134 | F39: 584.397 | G39: 1275.954 | H39: 1580.657 | I39: 0 | J39: 0 | K39: 0 | L39: 0 | M39: 0
A40: Non-current other financial assets | B40: INR crore | C40: 0 | D40: 1035.639 | E40: 819.522 | F40: 198.821 | G40: 5.83 | H40: 1.634 | I40: 2091.122 | J40: 2449.966 | K40: 5296.216 | L40: 7493.3 | M40: 7110.7
A41: Deferred tax assets | B41: INR crore | C41: 0 | D41: 0 | E41: 0 | F41: 0.967 | G41: 299.282 | H41: 302.693 | I41: 294.944 | J41: 294.944 | K41: 419.188 | L41: 419.2 | M41: 0
A42: Income tax assets | B42: INR crore | C42: 0 | D42: 9.76 | E42: 38.639 | F42: 124.049 | G42: 429.671 | H42: 513.953 | I42: 711.922 | J42: 1099.787 | K42: 1610.098 | L42: 1708 | M42: 1977.5
...

Sheet 03_Raw_Operating_KPIs
A1: Historical Operating KPIs
A2: InterGlobe Aviation Limited | FY2016-FY2026
A3: Company full-year disclosures. Later-year traffic metrics include non-scheduled operations where stated.
A5: Metric | B5: Unit | C5: FY2016 | D5: FY2017 | E5: FY2018 | F5: FY2019 | G5: FY2020 | H5: FY2021 | I5: FY2022 | J5: FY2023 | K5: FY2024 | L5: FY2025 | M5: FY2026
A6: Source document | C6: FY2016 AR / FY2017 Q4 | D6: FY2017 Q4 / AR | E6: FY2018 Q4 / AR | F6: FY2019 Q4 / AR | G6: FY2020 Q4 / AR | H6: FY2021 Q4 / AR | I6: FY2022 Q4 / AR | J6: FY2023 Q4 / AR | K6: FY2024 Q4 / AR | L6: FY2025 Q4 / AR | M6: FY2026 Q4 / AR
A8: Traffic and Capacity
A9: ASK (available seat km) | B9: billion | C9: 42.83 | D9: 54.58 | E9: 63.5 | F9: 81 | G9: 96.2 | H9: 45.4 | I9: 70.4 | J9: 114.4 | K9: 139.3 | L9: 157.5 | M9: 172.4
A10: RPK (revenue passengers km) | B10: billion | C10: 35.97 | D10: 46.29 | E10: 55.5 | F10: 69.8 | G10: 82.5 | H10: 31.5 | I10: 51.8 | J10: 93.9 | K10: 119.7 | L10: 135.4 | M10: 145.5
A11: Load factor | B11: % | C11: =C10/C9 -> 0.83983189 | D11: =D10/D9 -> 0.84811286 | E11: =E10/E9 -> 0.87401575 | F11: =F10/F9 -> 0.8617284 | G11: =G10/G9 -> 0.85758836 | H11: =H10/H9 -> 0.6938326 | I11: =I10/I9 -> 0.73579545 | J11: =J10/J9 -> 0.8208042 | ... M11: =M10/M9 -> 0.84396752
A12: Passengers | B12: million | C12: 33.104 | D12: 43.532 | E12: 52.142 | F12: 64.743 | G12: 75.026 | H12: 30.7 | I12: 49.8 | J12: 85.6 | K12: 106.7 | L12: 118.6 | M12: 123.4
A14: Unit Revenue and Cost
A15: Yield | B15: INR / passenger km | C15: 3.91 | D15: 3.5 | E15: 3.59 | F15: 3.6 | G15: 3.81 | H15: 3.76 | I15: 4.24 | J15: 5.13 | K15: 5.08 | L15: 5.15 | M15: 5.06
A16: RASK | B16: INR / ASK | C16: 3.78 | D16: 3.44 | E16: 3.64 | F16: 3.57 | G16: 3.77 | H16: 3.3 | I16: 3.73 | J16: 4.8 | K16: 4.96 | L16: 5.14 | M16: 4.99
A17: CASK | B17: INR / ASK | C17: 3.12 | D17: 3.04 | E17: 3.15 | F17: 3.59 | G17: 3.8 | H17: 4.58 | I17: 4.6 | J17: 4.83 | K17: 4.38 | L17: 4.66 | M17: 5
A18: Ex-fuel CASK | B18: INR / ASK | C18: 2.01 | D18: 1.88 | E18: 1.93 | F18: 2.11 | G18: 2.5 | H18: 3.74 | I18: 3.22 | J18: 2.76 | K18: 2.66 | L18: 3 | M18: 3.52
A19: Fuel CASK | B19: INR / ASK | C19: =C17-C18 -> 1.11 | D19: =D17-D18 -> 1.16 | E19: =E17-E18 -> 1.22 | F19: =F17-F18 -> 1.48 | G19: =G17-G18 -> 1.3 | H19: =H17-H18 -> 0.84 | I19: =I17-I18 -> 1.38 | J19: =J17-J18 -> 2.07 | ... M19: =M17-M18 -> 1.48
A21: Network and Fleet
A22: Closing fleet | B22: aircraft | C22: 107 | D22: 131 | E22: 159 | F22: 217 | G22: 262 | H22: 285 | I22: 275 | J22: 304 | K22: 367 | L22: 434 | M22: 441
A23: Net fleet additions | B23: aircraft | D23: =D22-C22 -> 24 | E23: =E22-D22 -> 28 | F23: =F22-E22 -> 58 | G23: =G22-F22 -> 45 | H23: =H22-G22 -> 23 | I23: =I22-H22 -> -10 | J23: =J22-I22 -> 29 | K23: =K22-J22 -> 63 | ... M23: =M22-L22 -> 7
A24: Peak daily flights | B24: flights | C24: 731 | D24: 896 | E24: 1086 | F24: 1376 | G24: 1674 | H24: 1301 | I24: 1577 | J24: 1815 | K24: 2021 | L24: 2304 | M24: 2241
A25: Domestic destinations | B25: destinations | C25: 35 | D25: 38 | E25: 42 | F25: 52 | G25: 62 | H25: 65 | I25: 73 | J25: 78 | K25: 88 | L25: 91 | M25: 97
A26: International destinations | B26: destinations | C26: 5 | D26: 6 | E26: 8 | F26: 16 | G26: 24 | H26: 10 | I26: 15 | J26: 22 | K26: 30 | L26: 40 | M26: 45
A27: Total destinations | B27: destinations | C27: =C25+C26 -> 40 | D27: =D25+D26 -> 44 | E27: =E25+E26 -> 50 | F27: =F25+F26 -> 68 | G27: =G25+G26 -> 86 | H27: =H25+H26 -> 75 | I27: =I25+I26 -> 88 | J27: =J25+J26 -> 100 | ... M27: =M25+M26 -> 142

Sheet 04_Industry_Data
A1: Indian Aviation Industry Context
A2: External demand and market-position benchmarks supporting capacity assumptions
A3: Calendar-year industry data is shown separately from IndiGo fiscal-year forecasts.
A5: Metric | B5: Unit | C5: 2023A | D5: 2024A | E5: 2025A | F5: Source / read-across
A8: Industry Traffic
A9: Total passengers at Indian airports | B9: million | C9: 369.85 | D9: 400.95 | E9: 420.03 | F9: Ministry of Civil Aviation annual reports
A10: Growth | B10: % | D10: =D9/C9-1 -> 0.084088144 | E10: =E9/D9-1 -> 0.047586981
A11: Domestic passengers at Indian airports | B11: million | C11: 302.92 | D11: 325.49 | E11: 338.91 | F11: Ministry of Civil Aviation annual reports
A12: Growth | B12: % | D12: =D11/C11-1 -> 0.074508121 | E12: =E11/D11-1 -> 0.041230145
A13: Total aircraft movements | B13: 000 movements | C13: 2656.43 | D13: 2815.55 | E13: 2899.5 | F13: Ministry of Civil Aviation annual reports
A14: Growth | B14: % | D14: =D13/C13-1 -> 0.059899941 | E14: =E13/D13-1 -> 0.029816554
A16: Market Position
A17: IndiGo domestic market share | B17: % | E17: 0.642 | F17: DGCA data, August 2025
A19: Model Read-Across
A20: FY2027E ASK growth | B20: % | E20: ='06_Operating_Model'!F19 -> 0.044571429
A21: FY2027E passenger growth | B21: % | E21: ='06_Operating_Model'!F29 -> 0.031409589
A22: Interpretation | C22: Recent industry passenger growth is 4.8%; FY2027E capacity growth of 4.5% is broadly aligned with recent demand growth.
A24: Sources | C24: Ministry of Civil Aviation annual reports for 2024-25 and 2025; IndiGo October 2025 newsletter citing DGCA.

Sheet 05_Historical_Analysis
A1: Historical Analysis
A2: InterGlobe Aviation Limited | FY2016-FY2026
A3: Historical calculations linked to reported financial statements and operating KPIs. FY2020 is the Ind AS 116 accounting break; pre-FY2020 and post-FY2020 lease-based returns are not directly comparable.
A5: Metric | B5: Unit | C5: FY2016 | D5: FY2017 | E5: FY2018 | F5: FY2019 | G5: FY2020 | H5: FY2021 | I5: FY2022 | J5: FY2023 | K5: FY2024 | L5: FY2025 | M5: FY2026
A6: Operating period | C6: Pre-COVID | D6: Pre-COVID | E6: Pre-COVID | F6: Pre-COVID | G6: Ind AS 116 transition | H6: COVID disruption | I6: COVID disruption | J6: Recovery | K6: Normalized recent | L6: Normalized recent | M6: Recent / FX-distorted
A8: Growth and Network Expansion
A9: Revenue growth | B9: % | D9: =IFERROR(D58/C58-1,"") -> 0.15121467 | E9: =IFERROR(E58/D58-1,"") -> 0.23898103 | F9: =IFERROR(F58/E58-1,"") -> 0.23786594 | G9: =IFERROR(G58/F58-1,"") -> 0.25473864 | H9: =IFERROR(H58/G58-1,"") -> -0.59054059 | I9: =IFERROR(I58/H58-1,"") -> 0.77116184 | J9: =IFERROR(J58/I58-1,"") -> 1.0996724 | K9: =IFERROR(K58/J58-1,"") -> 0.26554327 | ... M9: =IFERROR(M58/L58-1,"") -> 0.051470925
A10: Passenger growth | B10: % | D10: =IFERROR(D89/C89-1,"") -> 0.31500725 | E10: =IFERROR(E89/D89-1,"") -> 0.19778554 | F10: =IFERROR(F89/E89-1,"") -> 0.24166699 | G10: =IFERROR(G89/F89-1,"") -> 0.15882798 | H10: =IFERROR(H89/G89-1,"") -> -0.59080852 | I10: =IFERROR(I89/H89-1,"") -> 0.62214984 | J10: =IFERROR(J89/I89-1,"") -> 0.7188755 | K10: =IFERROR(K89/J89-1,"") -> 0.24649533 | ... M10: =IFERROR(M89/L89-1,"") -> 0.040472175
A11: ASK growth | B11: % | D11: =IFERROR(D87/C87-1,"") -> 0.27434042 | E11: =IFERROR(E87/D87-1,"") -> 0.16342983 | F11: =IFERROR(F87/E87-1,"") -> 0.27559055 | G11: =IFERROR(G87/F87-1,"") -> 0.18765432 | H11: =IFERROR(H87/G87-1,"") -> -0.52806653 | I11: =IFERROR(I87/H87-1,"") -> 0.55066079 | J11: =IFERROR(J87/I87-1,"") -> 0.625 | K11: =IFERROR(K87/J87-1,"") -> 0.21765734 | ... M11: =IFERROR(M87/L87-1,"") -> 0.094603175
A12: RPK growth | B12: % | D12: =IFERROR(D88/C88-1,"") -> 0.28690575 | E12: =IFERROR(E88/D88-1,"") -> 0.19896306 | F12: =IFERROR(F88/E88-1,"") -> 0.25765766 | G12: =IFERROR(G88/F88-1,"") -> 0.18194842 | H12: =IFERROR(H88/G88-1,"") -> -0.61818182 | I12: =IFERROR(I88/H88-1,"") -> 0.64444444 | J12: =IFERROR(J88/I88-1,"") -> 0.81274131 | K12: =IFERROR(K88/J88-1,"") -> 0.27476038 | ... M12: =IFERROR(M88/L88-1,"") -> 0.074593796
A13: Fleet growth | B13: % | D13: =IFERROR(D90/C90-1,"") -> 0.22429907 | E13: =IFERROR(E90/D90-1,"") -> 0.21374046 | F13: =IFERROR(F90/E90-1,"") -> 0.36477987 | G13: =IFERROR(G90/F90-1,"") -> 0.20737327 | H13: =IFERROR(H90/G90-1,"") -> 0.08778626 | I13: =IFERROR(I90/H90-1,"") -> -0.035087719 | J13: =IFERROR(J90/I90-1,"") -> 0.10545455 | K13: =IFERROR(K90/J90-1,"") -> 0.20723684 | ... M13: =IFERROR(M90/L90-1,"") -> 0.016129032
A14: International destinations growth (capacity proxy) | B14: % | D14: =IFERROR(D91/C91-1,"") -> 0.2 | E14: =IFERROR(E91/D91-1,"") -> 0.33333333 | F14: =IFERROR(F91/E91-1,"") -> 1 | G14: =IFERROR(G91/F91-1,"") -> 0.5 | H14: =IFERROR(H91/G91-1,"") -> -0.58333333 | I14: =IFERROR(I91/H91-1,"") -> 0.5 | J14: =IFERROR(J91/I91-1,"") -> 0.46666667 | K14: =IFERROR(K91/J91-1,"") -> 0.36363636 | ... M14: =IFERROR(M91/L91-1,"") -> 0.125
A15: Peak daily flights growth | B15: % | D15: =IFERROR(D92/C92-1,"") -> 0.22571819 | E15: =IFERROR(E92/D92-1,"") -> 0.21205357 | F15: =IFERROR(F92/E92-1,"") -> 0.26703499 | G15: =IFERROR(G92/F92-1,"") -> 0.21656977 | H15: =IFERROR(H92/G92-1,"") -> -0.22281959 | I15: =IFERROR(I92/H92-1,"") -> 0.2121445 | J15: =IFERROR(J92/I92-1,"") -> 0.15091947 | K15: =IFERROR(K92/J92-1,"") -> 0.11349862 | ... M15: =IFERROR(M92/L92-1,"") -> -0.02734375
A17: Unit Economics
A18: Load factor | B18: % | C18: =C93 -> 0.83983189 | D18: =D93 -> 0.84811286 | E18: =E93 -> 0.87401575 | F18: =F93 -> 0.8617284 | G18: =G93 -> 0.85758836 | H18: =H93 -> 0.6938326 | I18: =I93 -> 0.73579545 | J18: =J93 -> 0.8208042 | ... M18: =M93 -> 0.84396752
A19: Yield | B19: INR / passenger km | C19: =C94 -> 3.91 | D19: =D94 -> 3.5 | E19: =E94 -> 3.59 | F19: =F94 -> 3.6 | G19: =G94 -> 3.81 | H19: =H94 -> 3.76 | I19: =I94 -> 4.24 | J19: =J94 -> 5.13 | ... M19: =M94 -> 5.06
A20: Reported RASK | B20: INR / ASK | C20: =C95 -> 3.78 | D20: =D95 -> 3.44 | E20: =E95 -> 3.64 | F20: =F95 -> 3.57 | G20: =G95 -> 3.77 | H20: =H95 -> 3.3 | I20: =I95 -> 3.73 | J20: =J95 -> 4.8 | ... M20: =M95 -> 4.99
A21: Reported CASK | B21: INR / ASK | C21: =C96 -> 3.12 | D21: =D96 -> 3.04 | E21: =E96 -> 3.15 | F21: =F96 -> 3.59 | G21: =G96 -> 3.8 | H21: =H96 -> 4.58 | I21: =I96 -> 4.6 | J21: =J96 -> 4.83 | ... M21: =M96 -> 5
A22: Reported ex-fuel CASK | B22: INR / ASK | C22: =C97 -> 2.01 | D22: =D97 -> 1.88 | E22: =E97 -> 1.93 | F22: =F97 -> 2.11 | G22: =G97 -> 2.5 | H22: =H97 -> 3.74 | I22: =I97 -> 3.22 | J22: =J97 -> 2.76 | ... M22: =M97 -> 3.52
A23: Revenue / ASK | B23: INR / ASK | C23: =IFERROR(C58/C87/100,"") -> 3.7683654 | D23: =IFERROR(D58/D87/100,"") -> 3.404269 | E23: =IFERROR(E58/E87/100,"") -> 3.6253365 | F23: =IFERROR(F58/F87/100,"") -> 3.51812 | G23: =IFERROR(G58/G87/100,"") -> 3.71684 | H23: =IFERROR(H58/H87/100,"") -> 3.2248086 | I23: =IFERROR(I58/I87/100,"") -> 3.6833703 | J23: =IFERROR(J58/J87/100,"") -> 4.7593053 | ... M23: =IFERROR(M58/M87/100,"") -> 4.9281845
A24: Fuel cost / ASK | B24: INR / ASK | C24: =IFERROR(C59/C87/100,"") -> 1.1158823 | D24: =IFERROR(D59/D87/100,"") -> 1.1618749 | E24: =IFERROR(E59/E87/100,"") -> 1.2220687 | F24: =IFERROR(F59/F87/100,"") -> 1.4744189 | G24: =IFERROR(G59/G87/100,"") -> 1.2945732 | H24: =IFERROR(H59/H87/100,"") -> 0.84389361 | I24: =IFERROR(I59/I87/100,"") -> 1.3771642 | J24: =IFERROR(J59/J87/100,"") -> 2.0669595 | ... M24: =IFERROR(M59/M87/100,"") -> 1.4726914
A25: Employee cost / ASK | B25: INR / ASK | C25: =IFERROR(C60/C87/100,"") -> 0.41791338 | D25: =IFERROR(D60/D87/100,"") -> 0.37526383 | E25: =IFERROR(E60/E87/100,"") -> 0.38661764 | F25: =IFERROR(F60/F87/100,"") -> 0.39636506 | G25: =IFERROR(G60/G87/100,"") -> 0.48960073 | H25: =IFERROR(H60/H87/100,"") -> 0.7258793 | I25: =IFERROR(I60/I87/100,"") -> 0.49523338 | J25: =IFERROR(J60/J87/100,"") -> 0.41912168 | ... M25: =IFERROR(M60/M87/100,"") -> 0.47982599
A26: Supplementary rentals and maintenance / ASK | B26: INR / ASK | C26: =IF(C61=0,"",C61/C87/100) | D26: =IF(D61=0,"",D61/D87/100) | E26: =IF(E61=0,"",E61/E87/100) | F26: =IF(F61=0,"",F61/F87/100) | G26: =IF(G61=0,"",G61/G87/100) -> 0.6098999 | H26: =IF(H61=0,"",H61/H87/100) -> 0.92318502 | I26: =IF(I61=0,"",I61/I87/100) -> 0.86502614 | J26: =IF(J61=0,"",J61/J87/100) -> 0.70323077 | ... M26: =IF(M61=0,"",M61/M87/100) -> 0.74896172
A27: EBITDAR proxy / ASK | B27: INR / ASK | C27: =IFERROR(C70/C87/100,"") -> 1.3332461 | D27: =IFERROR(D70/D87/100,"") -> 1.0381785 | E27: =IFERROR(E70/E87/100,"") -> 1.1201123 | F27: =IFERROR(F70/F87/100,"") -> 0.70200037 | G27: =IFERROR(G70/G87/100,"") -> 0.6064052 | H27: =IFERROR(H70/H87/100,"") -> 0.25922643 | I27: =IFERROR(I70/I87/100,"") -> 0.21549574 | J27: =IFERROR(J70/J87/100,"") -> 0.6981118 | ... M27: =IFERROR(M70/M87/100,"") -> 0.9000348
A28: EBITDA / ASK | B28: INR / ASK | C28: =IFERROR(C69/C87/100,"") -> 0.72335769 | D28: =IFERROR(D69/D87/100,"") -> 0.46555606 | E28: =IFERROR(E69/E87/100,"") -> 0.55157701 | F28: =IFERROR(F69/F87/100,"") -> 0.084784444 | G28: =IFERROR(G69/G87/100,"") -> 0.55477765 | H28: =IFERROR(H69/H87/100,"") -> 0.19745176 | I28: =IFERROR(I69/I87/100,"") -> 0.17122244 | J28: =IFERROR(J69/J87/100,"") -> 0.66962928 | ... M28: =IFERROR(M69/M87/100,"") -> 0.77911253
A29: EBIT / ASK | B29: INR / ASK | C29: =IFERROR(C68/C87/100,"") -> 0.6058982 | D29: =IFERROR(D68/D87/100,"") -> 0.38177941 | E29: =IFERROR(E68/E87/100,"") -> 0.48277748 | F29: =IFERROR(F68/F87/100,"") -> -0.0089908642 | G29: =IFERROR(G68/G87/100,"") -> 0.14168732 | H29: =IFERROR(H68/H87/100,"") -> -0.8376685 | I29: =IFERROR(I68/I87/100,"") -> -0.54874915 | J29: =IFERROR(J68/J87/100,"") -> 0.22356556 | ... M29: =IFERROR(M68/M87/100,"") -> 0.15218677
A30: Revenue / passenger | B30: INR / passenger | C30: =IFERROR(C58*10/C89,"") -> 4875.5163 | D30: =IFERROR(D58*10/D89,"") -> 4268.2395 | E30: =IFERROR(E58*10/E89,"") -> 4415.0372 | F30: =IFERROR(F58*10/F89,"") -> 4401.5217 | G30: =IFERROR(G58*10/G89,"") -> 4765.8147 | H30: =IFERROR(H58*10/H89,"") -> 4768.9352 | I30: =IFERROR(I58*10/I89,"") -> 5207.0135 | J30: =IFERROR(J58*10/J89,"") -> 6360.5669 | ... M30: =IFERROR(M58*10/M89,"") -> 6885.081
A31: PAT / passenger | B31: INR / passenger | C31: =IFERROR(C71*10/C89,"") -> 601.05123 | D31: =IFERROR(D71*10/D89,"") -> 381.13273 | E31: =IFERROR(E71*10/E89,"") -> 430.04181 | F31: =IFERROR(F71*10/F89,"") -> 24.287877 | G31: =IFERROR(G71*10/G89,"") -> -31.146269 | H31: =IFERROR(H71*10/H89,"") -> -1891.3443 | I31: =IFERROR(I71*10/I89,"") -> -1237.3183 | J31: =IFERROR(J71*10/J89,"") -> -35.723014 | ... M31: =IFERROR(M71*10/M89,"") -> -193.97083
A32: Margins and Returns
A33: EBITDAR proxy margin | B33: % | C33: =IFERROR(C70/C58,"") -> 0.35379958 | D33: =IFERROR(D70/D58,"") -> 0.3049637 | E33: =IFERROR(E70/E58,"") -> 0.30896781 | F33: =IFERROR(F70/F58,"") -> 0.1995385 | G33: =IFERROR(G70/G58,"") -> 0.16315074 | H33: =IFERROR(H70/H58,"") -> 0.08038506 | I33: =IFERROR(I70/I58,"") -> 0.058505043 | J33: =IFERROR(J70/J58,"") -> 0.14668355 | ... M33: =IFERROR(M70/M58,"") -> 0.1826301
A34: EBITDA margin | B34: % | C34: =IFERROR(C69/C58,"") -> 0.1919553 | D34: =IFERROR(D69/D58,"") -> 0.13675655 | E34: =IFERROR(E69/E58,"") -> 0.15214505 | F34: =IFERROR(F69/F58,"") -> 0.024099361 | G34: =IFERROR(G69/G58,"") -> 0.14926057 | H34: =IFERROR(H69/H58,"") -> 0.061228987 | I34: =IFERROR(I69/I58,"") -> 0.046485264 | J34: =IFERROR(J69/J58,"") -> 0.14069895 | ... M34: =IFERROR(M69/M58,"") -> 0.15809322
A35: EBIT margin | B35: % | C35: =IFERROR(C68/C58,"") -> 0.16078542 | D35: =IFERROR(D68/D58,"") -> 0.11214725 | E35: =IFERROR(E68/E58,"") -> 0.13316763 | F35: =IFERROR(F68/F58,"") -> -0.0025555877 | G35: =IFERROR(G68/G58,"") -> 0.03812037 | H35: =IFERROR(H68/H58,"") -> -0.25975759 | I35: =IFERROR(I68/I58,"") -> -0.14898017 | J35: =IFERROR(J68/J58,"") -> 0.04697441 | ... M35: =IFERROR(M68/M58,"") -> 0.030880901
A36: PAT margin | B36: % | C36: =IFERROR(C71/C58,"") -> 0.12327951 | D36: =IFERROR(D71/D58,"") -> 0.089295067 | E36: =IFERROR(E71/E58,"") -> 0.097403892 | F36: =IFERROR(F71/F58,"") -> 0.0055180636 | G36: =IFERROR(G71/G58,"") -> -0.0065353505 | H36: =IFERROR(H71/H58,"") -> -0.39659677 | I36: =IFERROR(I71/I58,"") -> -0.23762533 | J36: =IFERROR(J71/J58,"") -> -0.0056163255 | ... M36: =IFERROR(M71/M58,"") -> -0.028172628
A37: ROE | B37: % | D37: =IF(AVERAGE(C75,D75)>0,D71/AVERAGE(C75,D75),"") -> 0.59113241 | E37: =IF(AVERAGE(D75,E75)>0,E71/AVERAGE(D75,E75),"") -> 0.41308296 | F37: =IF(AVERAGE(E75,F75)>0,F71/AVERAGE(E75,F75),"") -> 0.022426749 | G37: =IF(AVERAGE(F75,G75)>0,G71/AVERAGE(F75,G75),"") -> -0.036444566 | H37: =IF(AVERAGE(G75,H75)>0,H71/AVERAGE(G75,H75),"") -> -1.9390956 | I37: =IF(AVERAGE(H75,I75)>0,I71/AVERAGE(H75,I75),"") | J37: =IF(AVERAGE(I75,J75)>0,J71/AVERAGE(I75,J75),"") | K37: =IF(AVERAGE(J75,K75)>0,K71/AVERAGE(J75,K75),"") | ... M37: =IF(AVERAGE(L75,M75)>0,M71/AVERAGE(L75,M75),"") -> -0.29269486
A39: Asset turnover | B39: x | D39: =IFERROR(D58/AVERAGE(C74,D74),"") -> 1.3164193 | E39: =IFERROR(E58/AVERAGE(D74,E74),"") -> 1.2670061 | F39: =IFERROR(F58/AVERAGE(E74,F74),"") -> 1.2347988 | G39: =IFERROR(G58/AVERAGE(F74,G74),"") -> 1.0653094 | H39: =IFERROR(H58/AVERAGE(G74,H74),"") -> 0.34386958 | I39: =IFERROR(I58/AVERAGE(H74,I74),"") -> 0.58262744 | J39: =IFERROR(J58/AVERAGE(I74,J74),"") -> 1.0357691 | K39: =IFERROR(K58/AVERAGE(J74,K74),"") -> 0.97464077 | ... M39: =IFERROR(M58/AVERAGE(L74,M74),"") -> 0.67471419
A40: Effective tax rate | B40: % | C40: =IF(C66>0,C67/C66,"") -> 0.29665777 | D40: =IF(D66>0,D67/D66,"") -> 0.22625203 | E40: =IF(E66>0,E67/E66,"") -> 0.28282971 | F40: =IF(F66>0,F67/F66,"") | G40: =IF(G66>0,G67/G66,"") | H40: =IF(H66>0,H67/H66,"") | I40: =IF(I66>0,I67/I66,"") | J40: =IF(J66>0,J67/J66,"") | ... M40: =IF(M66>0,M67/M66,"")
A42: Cash Conversion
A44: CFO / EBITDA | B44: x | C44: =IFERROR(C72/C69,"") -> 1.0003015 | D44: =IFERROR(D72/D69,"") -> 1.488415 | E44: =IFERROR(E72/E69,"") -> 1.1143664 | F44: =IFERROR(F72/F69,"") -> 4.6239862 | G44: =IFERROR(G72/G69,"") -> 1.3063206 | H44: =IFERROR(H72/H69,"") -> -1.800645 | I44: =IFERROR(I72/I69,"") -> 1.7343352 | J44: =IFERROR(J72/J69,"") -> 1.6614896 | ... M44: =IFERROR(M72/M69,"") -> 1.7473254
A45: FCF / revenue | B45: % | C45: =IFERROR(C73/C58,"") -> 0.17763948 | D45: =IFERROR(D73/D58,"") -> 0.19078238 | E45: =IFERROR(E73/E58,"") -> 0.11654064 | F45: =IFERROR(F73/F58,"") -> 0.051373503 | G45: =IFERROR(G73/G58,"") -> 0.16454513 | H45: =IFERROR(H73/H58,"") -> -0.14009239 | I45: =IFERROR(I73/I58,"") -> 0.067243913 | J45: =IFERROR(J73/J58,"") -> 0.22330445 | ... M45: =IFERROR(M73/M58,"") -> 0.24950125
A48: Balance Sheet and Leverage
...

Sheet 06_Operating_Model
A1: Driver-Based Operating Model
A2: InterGlobe Aviation Limited | FY2024A-FY2031E
A3: Base case uses recent actual operating economics. FY2027 annual assumptions are analyst inputs, not company guidance; fuel and currency sensitivities are summarized separately.
A5: Metric | B5: Unit | C5: FY2024A | D5: FY2025A | E5: FY2026A | F5: FY2027E | G5: FY2028E | H5: FY2029E | I5: FY2030E | J5: FY2031E
A6: Period | C6: Actual | D6: Actual | E6: Actual | F6: Forecast | G6: Forecast | H6: Forecast | I6: Forecast | J6: Forecast
A8: Fleet and Capacity
A9: Beginning fleet | B9: aircraft | C9: ='03_Raw_Operating_KPIs'!J22 -> 304 | D9: ='03_Raw_Operating_KPIs'!K22 -> 367 | E9: ='03_Raw_Operating_KPIs'!L22 -> 434 | F9: =E13 -> 441 | G9: =F13 -> 473 | H9: =G13 -> 511 | I9: =H13 -> 551 | J9: =I13 -> 589
A10: Aircraft deliveries | B10: aircraft | F10: 42 | G10: 46 | H10: 48 | I10: 48 | J10: 45
A11: Aircraft retirements | B11: aircraft | F11: 10 | G11: 8 | H11: 8 | I11: 10 | J11: 10
A12: Net fleet additions | B12: aircraft | C12: ='03_Raw_Operating_KPIs'!K23 -> 63 | D12: ='03_Raw_Operating_KPIs'!L23 -> 67 | E12: ='03_Raw_Operating_KPIs'!M23 -> 7 | F12: =F10-F11 -> 32 | G12: =G10-G11 -> 38 | H12: =H10-H11 -> 40 | I12: =I10-I11 -> 38 | J12: =J10-J11 -> 35
A13: Ending fleet | B13: aircraft | C13: ='03_Raw_Operating_KPIs'!K22 -> 367 | D13: ='03_Raw_Operating_KPIs'!L22 -> 434 | E13: ='03_Raw_Operating_KPIs'!M22 -> 441 | F13: =F9+F12 -> 473 | G13: =G9+G12 -> 511 | H13: =H9+H12 -> 551 | I13: =I9+I12 -> 589 | J13: =J9+J12 -> 624
A14: Fleet growth | B14: % | C14: =C13/C9-1 -> 0.20723684 | D14: =D13/D9-1 -> 0.18256131 | E14: =E13/E9-1 -> 0.016129032 | F14: =F13/F9-1 -> 0.072562358 | G14: =G13/G9-1 -> 0.080338266 | H14: =H13/H9-1 -> 0.078277886 | I14: =I13/I9-1 -> 0.068965517 | J14: =J13/J9-1 -> 0.05942275
A15: Average fleet | B15: aircraft | C15: =AVERAGE(C9,C13) -> 335.5 | D15: =AVERAGE(D9,D13) -> 400.5 | E15: =AVERAGE(E9,E13) -> 437.5 | F15: =AVERAGE(F9,F13) -> 457 | G15: =AVERAGE(G9,G13) -> 492 | H15: =AVERAGE(H9,H13) -> 531 | I15: =AVERAGE(I9,I13) -> 570 | J15: =AVERAGE(J9,J13) -> 606.5
A16: ASK productivity / average aircraft | B16: bn ASK / aircraft | C16: ='03_Raw_Operating_KPIs'!K9/C15 -> 0.41520119 | D16: ='03_Raw_Operating_KPIs'!L9/D15 -> 0.39325843 | E16: ='03_Raw_Operating_KPIs'!M9/E15 -> 0.39405714 | F16: =E16*(1+F17) -> 0.39405714 | G16: =F16*(1+G17) -> 0.399968 | H16: =G16*(1+H17) -> 0.40596752 | I16: =H16*(1+I17) -> 0.41104211 | J16: =I16*(1+J17) -> 0.41618014
A17: ASK productivity growth | B17: % | D17: =D16/C16-1 -> -0.052848512 | E17: =E16/D16-1 -> 0.0020310204 | F17: 0 | G17: 0.015 | H17: 0.015 | I17: 0.0125 | J17: 0.0125
A18: ASK | B18: billion | C18: ='03_Raw_Operating_KPIs'!K9 -> 139.3 | D18: ='03_Raw_Operating_KPIs'!L9 -> 157.5 | E18: ='03_Raw_Operating_KPIs'!M9 -> 172.4 | F18: =F15*F16 -> 180.08411 | G18: =G15*G16 -> 196.78426 | H18: =H15*H16 -> 215.56875 | I18: =I15*I16 -> 234.294 | J18: =J15*J16 -> 252.41326
A19: ASK growth | B19: % | C19: ='05_Historical_Analysis'!K11 -> 0.21765734 | D19: ='05_Historical_Analysis'!L11 -> 0.13065327 | E19: ='05_Historical_Analysis'!M11 -> 0.094603175 | F19: =F18/E18-1 -> 0.044571429 | G19: =G18/F18-1 -> 0.09273523 | H19: =H18/G18-1 -> 0.095457317 | I19: =I18/H18-1 -> 0.086864407 | J19: =J18/I18-1 -> 0.077335526
A20: Capacity identity check | B20: aircraft | C20: =C13-C9-C12 -> 0 | D20: =D13-D9-D12 -> 0 | E20: =E13-E9-E12 -> 0 | F20: =F13-F9-F12 -> 0 | G20: =G13-G9-G12 -> 0 | H20: =H13-H9-H12 -> 0 | I20: =I13-I9-I12 -> 0 | J20: =J13-J9-J12 -> 0
A22: Traffic
A23: Load factor | B23: % | C23: ='03_Raw_Operating_KPIs'!K11 -> 0.85929648 | D23: ='03_Raw_Operating_KPIs'!L11 -> 0.85968254 | E23: ='03_Raw_Operating_KPIs'!M11 -> 0.84396752 | F23: 0.85 | G23: 0.855 | H23: 0.86 | I23: 0.865 | J23: 0.865
A24: RPK | B24: billion | C24: ='03_Raw_Operating_KPIs'!K10 -> 119.7 | D24: ='03_Raw_Operating_KPIs'!L10 -> 135.4 | E24: ='03_Raw_Operating_KPIs'!M10 -> 145.5 | F24: =F18*F23 -> 153.0715 | G24: =G18*G23 -> 168.25054 | H24: =H18*H23 -> 185.38913 | I24: =I18*I23 -> 202.66431 | J24: =J18*J23 -> 218.33747
A25: RPK growth | B25: % | C25: ='05_Historical_Analysis'!K12 -> 0.27476038 | D25: ='05_Historical_Analysis'!L12 -> 0.13116124 | E25: ='05_Historical_Analysis'!M12 -> 0.074593796 | F25: =F24/E24-1 -> 0.052037781 | G25: =G24/F24-1 -> 0.099163084 | H25: =H24/G24-1 -> 0.1018635 | I25: =I24/H24-1 -> 0.093183386 | J25: =J24/I24-1 -> 0.077335526
A26: Passenger distance | B26: 000 km / passenger | C26: =C24/C28 -> 1.1218369 | D26: =D24/D28 -> 1.1416526 | E26: =E24/E28 -> 1.1790924 | F26: =E26*(1+F27) -> 1.2026742 | G26: =F26*(1+G27) -> 1.2267277 | H26: =G26*(1+H27) -> 1.2512623 | I26: =H26*(1+I27) -> 1.2700312 | J26: =I26*(1+J27) -> 1.2890817
A27: Passenger distance growth | B27: % | D27: =D26/C26-1 -> 0.017663608 | E27: =E26/D26-1 -> 0.032794362 | F27: 0.02 | G27: 0.02 | H27: 0.02 | I27: 0.015 | J27: 0.015
A28: Passengers | B28: million | C28: ='03_Raw_Operating_KPIs'!K12 -> 106.7 | D28: ='03_Raw_Operating_KPIs'!L12 -> 118.6 | E28: ='03_Raw_Operating_KPIs'!M12 -> 123.4 | F28: =F24/F26 -> 127.27594 | G28: =G24/G26 -> 137.15394 | H28: =H24/H26 -> 148.16169 | I28: =I24/I26 -> 159.57428 | J28: =J24/J26 -> 169.37442
A29: Passenger growth | B29: % | C29: ='05_Historical_Analysis'!K10 -> 0.24649533 | D29: ='05_Historical_Analysis'!L10 -> 0.11152765 | E29: ='05_Historical_Analysis'!M10 -> 0.040472175 | F29: =F28/E28-1 -> 0.031409589 | G29: =G28/F28-1 -> 0.077610867 | H29: =H28/G28-1 -> 0.080258334 | I29: =I28/H28-1 -> 0.077027966 | J29: =J28/I28-1 -> 0.061414312
A30: Traffic identity check | B30: billion | C30: =C24-C18*C23 -> 0 | D30: =D24-D18*D23 -> 0 | E30: =E24-E18*E23 -> 0 | F30: =F24-F18*F23 -> 0 | G30: =G24-G18*G23 -> 0 | H30: =H24-H18*H23 -> 0 | I30: =I24-I18*I23 -> 0 | J30: =J24-J18*J23 -> 0
A32: Revenue
A33: Yield | B33: INR / passenger km | C33: ='03_Raw_Operating_KPIs'!K15 -> 5.08 | D33: ='03_Raw_Operating_KPIs'!L15 -> 5.15 | E33: ='03_Raw_Operating_KPIs'!M15 -> 5.06 | F33: =E33*(1+F34) -> 5.4648 | G33: =F33*(1+G34) -> 5.656068 | H33: =G33*(1+H34) -> 5.82575 | I33: =H33*(1+I34) -> 5.9713938 | J33: =I33*(1+J34) -> 6.1206786
A34: Yield growth | B34: % | D34: =D33/C33-1 -> 0.013779528 | E34: =E33/D33-1 -> -0.017475728 | F34: 0.08 | G34: 0.035 | H34: 0.03 | I34: 0.025 | J34: 0.025
A35: Passenger PRASK | B35: INR / ASK | C35: =C33*C23 -> 4.3652261 | D35: =D33*D23 -> 4.4273651 | E35: =E33*E23 -> 4.2704756 | F35: =F33*F23 -> 4.64508 | G35: =G33*G23 -> 4.8359381 | H35: =H33*H23 -> 5.010145 | I35: =I33*I23 -> 5.1652556 | J35: =J33*J23 -> 5.294387
A36: Passenger PRASK growth | B36: % | D36: =D35/C35-1 -> 0.01423499 | E36: =E35/D35-1 -> -0.035436301 | F36: =F35/E35-1 -> 0.087719588 | G36: =G35/F35-1 -> 0.041088235 | H36: =H35/G35-1 -> 0.036023392 | I36: =I35/H35-1 -> 0.030959302 | J36: =J35/I35-1 -> 0.025
A37: Ancillary RASK | B37: INR / ASK | C37: =C40/C18/100 -> 0.58124494 | D37: =D40/D18/100 -> 0.70297778 | E37: =E40/E18/100 -> 0.65770882 | F37: =F40/F18/100 -> 0.68189261 | G37: =G40/G18/100 -> 0.70607738 | H37: =H40/H18/100 -> 0.72761351 | I37: =I40/I18/100 -> 0.74986953 | J37: =J40/J18/100 -> 0.76833923
A38: RASK - CASK spread | B38: INR / ASK | C38: =C44-C57 -> 0.57042096 | D38: =D44-D57 -> 0.46702222 | E38: =E44-E57 -> -0.064506961 | F38: =F44-F57 -> 0.014246626 | G38: =G44-G57 -> 0.10956006 | H38: =H44-H57 -> 0.15748341 | I38: =I44-I57 -> 0.18289885 | J38: =J44-J57 -> 0.19507738
A39: Passenger revenue | B39: INR crore | C39: =C24*C33*100 -> 60807.6 | D39: =D24*D33*100 -> 69731 | E39: =E24*E33*100 -> 73623 | F39: =F24*F33*100 -> 83650.512 | G39: =G24*G33*100 -> 95163.649 | H39: =H24*H33*100 -> 108003.07 | I39: =I24*I33*100 -> 121018.84 | J39: =J24*J33*100 -> 133637.35
A40: Ancillary and other operating revenue | B40: INR crore | C40: =C43-C39 -> 8096.742 | D40: =D43-D39 -> 11071.9 | E40: =E43-E39 -> 11338.9 | F40: =F28*F41/10 -> 12279.803 | G40: =G28*G41/10 -> 13894.491 | H40: =H28*H41/10 -> 15685.074 | I40: =I28*I41/10 -> 17568.994 | J40: =J28*J41/10 -> 19393.901
A41: Ancillary revenue / passenger | B41: INR / passenger | C41: =C40*10/C28 -> 758.83243 | D41: =D40*10/D28 -> 933.54975 | E41: =E40*10/E28 -> 918.87358 | F41: =E41*(1+F42) -> 964.81726 | G41: =F41*(1+G42) -> 1013.0581 | H41: =G41*(1+H42) -> 1058.6457 | I41: =H41*(1+I42) -> 1100.9916 | J41: =I41*(1+J42) -> 1145.0312
A42: Ancillary revenue / passenger growth | B42: % | D42: =D41/C41-1 -> 0.23024493 | E42: =E41/D41-1 -> -0.015720818 | F42: 0.05 | G42: 0.05 | H42: 0.045 | I42: 0.04 | J42: 0.04
A43: Revenue from operations | B43: INR crore | C43: ='02_Raw_Financials'!K8 -> 68904.342 | D43: ='02_Raw_Financials'!L8 -> 80802.9 | E43: ='02_Raw_Financials'!M8 -> 84961.9 | F43: =F39+F40 -> 95930.314 | G43: =G39+G40 -> 109058.14 | H43: =H39+H40 -> 123688.15 | I43: =I39+I40 -> 138587.84 | J43: =J39+J40 -> 153031.25
A44: Calculated RASK | B44: INR / ASK | C44: =C35+C37 -> 4.9464711 | D44: =D35+D37 -> 5.1303429 | E44: =E35+E37 -> 4.9281845 | F44: =F35+F37 -> 5.3269726 | G44: =G35+G37 -> 5.5420155 | H44: =H35+H37 -> 5.7377585 | I44: =I35+I37 -> 5.9151252 | J44: =J35+J37 -> 6.0627262
...

Sheet 07_Income_Statement
A1: Forecast Income Statement
A2: InterGlobe Aviation Limited | INR crore | FY2024A-FY2031E
A3: Base case linked to the operating model; finance costs are based on average lease-adjusted debt.
A5: Metric | B5: Unit | C5: FY2024A | D5: FY2025A | E5: FY2026A | F5: FY2027E | G5: FY2028E | H5: FY2029E | I5: FY2030E | J5: FY2031E
A6: Period | C6: Actual | D6: Actual | E6: Actual | F6: Forecast | G6: Forecast | H6: Forecast | I6: Forecast | J6: Forecast
A8: Revenue
A9: Passenger revenue | B9: INR crore | C9: ='06_Operating_Model'!C39 -> 60807.6 | D9: ='06_Operating_Model'!D39 -> 69731 | E9: ='06_Operating_Model'!E39 -> 73623 | F9: ='06_Operating_Model'!F39 -> 83650.512 | G9: ='06_Operating_Model'!G39 -> 95163.649 | H9: ='06_Operating_Model'!H39 -> 108003.07 | I9: ='06_Operating_Model'!I39 -> 121018.84 | J9: ='06_Operating_Model'!J39 -> 133637.35
A10: Ancillary and other operating revenue | B10: INR crore | C10: ='06_Operating_Model'!C40 -> 8096.742 | D10: ='06_Operating_Model'!D40 -> 11071.9 | E10: ='06_Operating_Model'!E40 -> 11338.9 | F10: ='06_Operating_Model'!F40 -> 12279.803 | G10: ='06_Operating_Model'!G40 -> 13894.491 | H10: ='06_Operating_Model'!H40 -> 15685.074 | I10: ='06_Operating_Model'!I40 -> 17568.994 | J10: ='06_Operating_Model'!J40 -> 19393.901
A11: Revenue from operations | B11: INR crore | C11: ='06_Operating_Model'!C43 -> 68904.342 | D11: ='06_Operating_Model'!D43 -> 80802.9 | E11: ='06_Operating_Model'!E43 -> 84961.9 | F11: ='06_Operating_Model'!F43 -> 95930.314 | G11: ='06_Operating_Model'!G43 -> 109058.14 | H11: ='06_Operating_Model'!H43 -> 123688.15 | I11: ='06_Operating_Model'!I43 -> 138587.84 | J11: ='06_Operating_Model'!J43 -> 153031.25
A12: Revenue growth | B12: % | D12: ='06_Operating_Model'!D48 -> 0.17268227 | E12: ='06_Operating_Model'!E48 -> 0.051470925 | F12: ='06_Operating_Model'!F48 -> 0.12909804 | G12: ='06_Operating_Model'!G48 -> 0.13684752 | H12: ='06_Operating_Model'!H48 -> 0.13414868 | I12: ='06_Operating_Model'!I48 -> 0.12046175 | J12: ='06_Operating_Model'!J48 -> 0.10421846
A13: Other income | B13: INR crore | C13: ='06_Operating_Model'!C60 -> 2326.821 | D13: ='06_Operating_Model'!D60 -> 3295.3 | E13: ='06_Operating_Model'!E60 -> 4551.5 | F13: ='06_Operating_Model'!F60 -> 3837.2126 | G13: ='06_Operating_Model'!G60 -> 4144.2093 | H13: ='06_Operating_Model'!H60 -> 4329.0851 | I13: ='06_Operating_Model'!I60 -> 4573.3986 | J13: ='06_Operating_Model'!J60 -> 4590.9374
A14: Total income | B14: INR crore | C14: =C11+C13 -> 71231.163 | D14: =D11+D13 -> 84098.2 | E14: =E11+E13 -> 89513.4 | F14: =F11+F13 -> 99767.527 | G14: =G11+G13 -> 113202.35 | H14: =H11+H13 -> 128017.23 | I14: =I11+I13 -> 143161.24 | J14: =J11+J13 -> 157622.18
A16: Operating Expenses and Profitability
A17: Aircraft fuel expense | B17: INR crore | C17: ='02_Raw_Financials'!K11 -> 23904.578 | D17: ='02_Raw_Financials'!L11 -> 26197.3 | E17: ='02_Raw_Financials'!M11 -> 25389.2 | F17: ='06_Operating_Model'!F53 -> 27846.875 | G17: ='06_Operating_Model'!G53 -> 29820.676 | H17: ='06_Operating_Model'!H53 -> 33320.623 | I17: ='06_Operating_Model'!I53 -> 36939.299 | J17: ='06_Operating_Model'!J53 -> 40591.94
A18: Aircraft and engine rentals | B18: INR crore | C18: ='02_Raw_Financials'!K12 -> 1075.195 | D18: ='02_Raw_Financials'!L12 -> 3010.3 | E18: ='02_Raw_Financials'!M12 -> 2084.7 | F18: ='06_Operating_Model'!F72 -> 2068.7372 | G18: ='06_Operating_Model'!G72 -> 2147.5529 | H18: ='06_Operating_Model'!H72 -> 2234.9249 | I18: ='06_Operating_Model'!I72 -> 2307.6073 | J18: ='06_Operating_Model'!J72 -> 2361.7639
A19: Other ex-fuel operating expenses | B19: INR crore | C19: =SUM('02_Raw_Financials'!K13:K19) -> 27606.998 | D19: =SUM('02_Raw_Financials'!L13:L19) -> 33537 | E19: =SUM('02_Raw_Financials'!M13:M19) -> 45504.6 | F19: ='06_Operating_Model'!F56-F18-F20 -> 54242.408 | G19: ='06_Operating_Model'!G56-G18-G20 -> 61972.783 | H19: ='06_Operating_Model'!H56-H18-H20 -> 70113.399 | I19: ='06_Operating_Model'!I56-I18-I20 -> 78763.668 | J19: ='06_Operating_Model'!J56-J18-J20 -> 87162.726
A20: Depreciation and amortisation | B20: INR crore | C20: ='02_Raw_Financials'!K20 -> 6425.729 | D20: ='02_Raw_Financials'!L20 -> 8680.2 | E20: ='02_Raw_Financials'!M20 -> 10808.2 | F20: ='06_Operating_Model'!F67 -> 11515.736 | G20: ='06_Operating_Model'!G67 -> 12961.16 | H20: ='06_Operating_Model'!H67 -> 14624.349 | I20: ='06_Operating_Model'!I67 -> 16292.051 | J20: ='06_Operating_Model'!J67 -> 17990.806
A21: Total operating expenses | B21: INR crore | C21: =SUM(C17:C20) -> 59012.5 | D21: =SUM(D17:D20) -> 71424.8 | E21: =SUM(E17:E20) -> 83786.7 | F21: =SUM(F17:F20) -> 95673.755 | G21: =SUM(G17:G20) -> 106902.17 | H21: =SUM(H17:H20) -> 120293.3 | I21: =SUM(I17:I20) -> 134302.63 | J21: =SUM(J17:J20) -> 148107.24
A22: EBIT before adjustment | B22: INR crore | C22: =C14-C21 -> 12218.663 | D22: =D14-D21 -> 12673.4 | E22: =E14-E21 -> 5726.7 | F22: =F14-F21 -> 4093.7717 | G22: =G14-G21 -> 6300.1788 | H22: =H14-H21 -> 7723.9354 | I22: =I14-I21 -> 8858.609 | J22: =J14-J21 -> 9514.9491
A23: Reported CASK / EBIT reconciliation | B23: INR crore | C23: ='06_Operating_Model'!C63-C22 -> -846.455 | D23: ='06_Operating_Model'!D63-D22 -> -1121.8 | E23: ='06_Operating_Model'!E63-E22 -> -3103 | F23: ='06_Operating_Model'!F63-F22 -> 0 | G23: ='06_Operating_Model'!G63-G22 -> -7.2759576e-12 | H23: ='06_Operating_Model'!H63-H22 -> 1.9099389e-11 | I23: ='06_Operating_Model'!I63-I22 -> -2.7284841e-11 | J23: ='06_Operating_Model'!J63-J22 -> 0
A24: Standardised EBIT | B24: INR crore | C24: =C22+C23 -> 11372.208 | D24: =D22+D23 -> 11551.6 | E24: =E22+E23 -> 2623.7 | F24: =F22+F23 -> 4093.7717 | G24: =G22+G23 -> 6300.1788 | H24: =H22+H23 -> 7723.9354 | I24: =I22+I23 -> 8858.609 | J24: =J22+J23 -> 9514.9491
A25: EBIT margin | B25: % | C25: =C24/C11 -> 0.16504342 | D25: =D24/D11 -> 0.14296022 | E25: =E24/E11 -> 0.030880901 | F25: =F24/F11 -> 0.042674432 | G25: =G24/G11 -> 0.057768992 | H25: =H24/H11 -> 0.062446852 | I25: =I24/I11 -> 0.063920537 | J25: =J24/J11 -> 0.062176512
A26: EBITDA | B26: INR crore | C26: =C24+C20 -> 17797.937 | D26: =D24+D20 -> 20231.8 | E26: =E24+E20 -> 13431.9 | F26: =F24+F20 -> 15609.507 | G26: =G24+G20 -> 19261.338 | H26: =H24+H20 -> 22348.284 | I26: =I24+I20 -> 25150.66 | J26: =J24+J20 -> 27505.755
A27: EBITDA margin | B27: % | C27: =C26/C11 -> 0.25829921 | D27: =D26/D11 -> 0.25038458 | E27: =E26/E11 -> 0.15809322 | F27: =F26/F11 -> 0.16271715 | G27: =G26/G11 -> 0.17661532 | H27: =H26/H11 -> 0.18068251 | I27: =I26/I11 -> 0.18147812 | J27: =J26/J11 -> 0.17973947
A28: EBITDAR | B28: INR crore | C28: =C26+C18 -> 18873.132 | D28: =D26+D18 -> 23242.1 | E28: =E26+E18 -> 15516.6 | F28: =F26+F18 -> 17678.244 | G28: =G26+G18 -> 21408.891 | H28: =H26+H18 -> 24583.209 | I28: =I26+I18 -> 27458.268 | J28: =J26+J18 -> 29867.519
A29: EBITDAR margin | B29: % | C29: =C28/C11 -> 0.27390338 | D29: =D28/D11 -> 0.28763943 | E29: =E28/E11 -> 0.1826301 | F29: =F28/F11 -> 0.18428215 | G29: =G28/G11 -> 0.19630714 | H29: =H28/H11 -> 0.19875154 | I29: =I28/I11 -> 0.19812899 | J29: =J28/J11 -> 0.19517268
A31: Below-the-Line Items
A32: Finance costs | B32: INR crore | C32: ='02_Raw_Financials'!K21 -> 4169.354 | D32: ='02_Raw_Financials'!L21 -> 5080 | E32: ='02_Raw_Financials'!M21 -> 5890.8 | F32: ='08_Balance_Sheet'!F77 -> 6219.936 | G32: ='08_Balance_Sheet'!G77 -> 6020.011 | H32: ='08_Balance_Sheet'!H77 -> 5779.7262 | I32: ='08_Balance_Sheet'!I77 -> 5661.6 | J32: ='08_Balance_Sheet'!J77 -> 5689.2306
A33: Finance costs / revenue | B33: % | C33: =C32/C11 -> 0.060509307 | D33: =D32/D11 -> 0.062869031 | E33: =E32/E11 -> 0.069334608 | F33: =F32/F11 -> 0.064838065 | G33: =G32/G11 -> 0.055200015 | H33: =H32/H11 -> 0.046728214 | I33: =I32/I11 -> 0.04085207 | J33: =J32/J11 -> 0.037176922
A34: Exceptional items | B34: INR crore | C34: ='02_Raw_Financials'!K23 -> 0 | D34: ='02_Raw_Financials'!L23 -> 0 | E34: ='02_Raw_Financials'!M23 -> 1796.4 | F34: 0 | G34: 0 | H34: 0 | I34: 0 | J34: 0
A35: Profit before tax | B35: INR crore | C35: ='02_Raw_Financials'!K24 -> 8049.309 | D35: ='02_Raw_Financials'!L24 -> 7593.4 | E35: ='02_Raw_Financials'!M24 -> -1960.5 | F35: =F24-F32-F34 -> -2126.1643 | G35: =G24-G32-G34 -> 280.16777 | H35: =H24-H32-H34 -> 1944.2092 | I35: =I24-I32-I34 -> 3197.009 | J35: =J24-J32-J34 -> 3825.7185
A36: Effective tax rate | B36: % | C36: =IF(C35=0,0,C37/C35) -> -0.015300568 | D36: =IF(D35=0,0,D37/D35) -> 0.04411726 | E36: =IF(E35=0,0,E37/E35) -> -0.22091303 | F36: 0.252 | G36: 0.252 | H36: 0.252 | I36: 0.252 | J36: 0.252
A37: Tax expense | B37: INR crore | C37: ='02_Raw_Financials'!K25 -> -123.159 | D37: ='02_Raw_Financials'!L25 -> 335 | E37: ='02_Raw_Financials'!M25 -> 433.1 | F37: =MAX(F35,0)*F36 -> 0 | G37: =MAX(G35,0)*G36 -> 70.602278 | H37: =MAX(H35,0)*H36 -> 489.94072 | I37: =MAX(I35,0)*I36 -> 805.64626 | J37: =MAX(J35,0)*J36 -> 964.08105
A38: Profit after tax | B38: INR crore | C38: ='02_Raw_Financials'!K26 -> 8172.468 | D38: ='02_Raw_Financials'!L26 -> 7258.4 | E38: ='02_Raw_Financials'!M26 -> -2393.6 | F38: =F35-F37 -> -2126.1643 | G38: =G35-G37 -> 209.56549 | H38: =H35-H37 -> 1454.2685 | I38: =I35-I37 -> 2391.3627 | J38: =J35-J37 -> 2861.6374
A39: PAT margin | B39: % | C39: =C38/C11 -> 0.11860599 | D39: =D38/D11 -> 0.089828459 | E39: =E38/E11 -> -0.028172628 | F39: =F38/F11 -> -0.022163633 | G39: =G38/G11 -> 0.0019215942 | H39: =H38/H11 -> 0.011757541 | I39: =I38/I11 -> 0.017255214 | J39: =J38/J11 -> 0.018699694
A41: Per Share
A42: Diluted weighted average shares | B42: crore shares | C42: ='02_Raw_Financials'!K26/'02_Raw_Financials'!K28 -> 38.620424 | D42: ='02_Raw_Financials'!L26/'02_Raw_Financials'!L28 -> 38.6764 | E42: ='02_Raw_Financials'!M26/'02_Raw_Financials'!M28 -> 38.681319 | F42: =E42*(1+F43) -> 38.681319 | G42: =F42*(1+G43) -> 38.681319 | H42: =G42*(1+H43) -> 38.681319 | I42: =H42*(1+I43) -> 38.681319 | J42: =I42*(1+J43) -> 38.681319
A43: Share count growth | B43: % | D43: =D42/C42-1 -> 0.0014493807 | E43: =E42/D42-1 -> 0.00012717361 | F43: 0 | G43: 0 | H43: 0 | I43: 0 | J43: 0
A44: Diluted EPS | B44: INR per share | C44: ='02_Raw_Financials'!K28 -> 211.61 | D44: ='02_Raw_Financials'!L28 -> 187.67 | E44: ='02_Raw_Financials'!M28 -> -61.88 | F44: =F38/F42 -> -54.96618 | G44: =G38/G42 -> 5.4177443 | H44: =H38/H42 -> 37.596146 | I44: =I38/I42 -> 61.822161 | J44: =J38/J42 -> 73.979831
A45: EPS growth | B45: % | D45: =IF(C44=0,0,D44/C44-1) -> -0.11313265 | E45: =IF(D44=0,0,E44/D44-1) -> -1.3297277 | F45: =IF(E44=0,0,F44/E44-1) -> -0.11172948 | G45: =IF(F44=0,0,G44/F44-1) -> -1.098565 | H45: =IF(G44=0,0,H44/G44-1) -> 5.9394464 | I45: =IF(H44=0,0,I44/H44-1) -> 0.64437496 | J45: =IF(I44=0,0,J44/I44-1) -> 0.19665553
...

Sheet 08_Balance_Sheet
A1: Balance Sheet: Fleet and Lease Schedules
A2: InterGlobe Aviation Limited | INR crore unless stated | FY2024A-FY2031E
A3: Fleet, leases, working capital and finance schedules supporting cash flow and valuation.
A5: Metric | B5: Unit | C5: FY2024A | D5: FY2025A | E5: FY2026A | F5: FY2027E | G5: FY2028E | H5: FY2029E | I5: FY2030E | J5: FY2031E
A6: Period | C6: Actual | D6: Actual | E6: Actual | F6: Forecast | G6: Forecast | H6: Forecast | I6: Forecast | J6: Forecast
A8: Fleet Bridge
A9: Beginning fleet | B9: aircraft | C9: ='06_Operating_Model'!C9 -> 304 | D9: ='06_Operating_Model'!D9 -> 367 | E9: ='06_Operating_Model'!E9 -> 434 | F9: ='06_Operating_Model'!F9 -> 441 | G9: ='06_Operating_Model'!G9 -> 473 | H9: ='06_Operating_Model'!H9 -> 511 | I9: ='06_Operating_Model'!I9 -> 551 | J9: ='06_Operating_Model'!J9 -> 589
A10: Aircraft deliveries | B10: aircraft | E10: 72 | F10: ='06_Operating_Model'!F10 -> 42 | G10: ='06_Operating_Model'!G10 -> 46 | H10: ='06_Operating_Model'!H10 -> 48 | I10: ='06_Operating_Model'!I10 -> 48 | J10: ='06_Operating_Model'!J10 -> 45
A11: Aircraft retirements | B11: aircraft | E11: 65 | F11: ='06_Operating_Model'!F11 -> 10 | G11: ='06_Operating_Model'!G11 -> 8 | H11: ='06_Operating_Model'!H11 -> 8 | I11: ='06_Operating_Model'!I11 -> 10 | J11: ='06_Operating_Model'!J11 -> 10
A12: Net fleet additions | B12: aircraft | C12: ='06_Operating_Model'!C12 -> 63 | D12: ='06_Operating_Model'!D12 -> 67 | E12: ='06_Operating_Model'!E12 -> 7 | F12: =F10-F11 -> 32 | G12: =G10-G11 -> 38 | H12: =H10-H11 -> 40 | I12: =I10-I11 -> 38 | J12: =J10-J11 -> 35
A13: Ending fleet | B13: aircraft | C13: ='06_Operating_Model'!C13 -> 367 | D13: ='06_Operating_Model'!D13 -> 434 | E13: ='06_Operating_Model'!E13 -> 441 | F13: ='06_Operating_Model'!F13 -> 473 | G13: ='06_Operating_Model'!G13 -> 511 | H13: ='06_Operating_Model'!H13 -> 551 | I13: ='06_Operating_Model'!I13 -> 589 | J13: ='06_Operating_Model'!J13 -> 624
A14: Fleet growth | B14: % | C14: ='06_Operating_Model'!C14 -> 0.20723684 | D14: ='06_Operating_Model'!D14 -> 0.18256131 | E14: ='06_Operating_Model'!E14 -> 0.016129032 | F14: ='06_Operating_Model'!F14 -> 0.072562358 | G14: ='06_Operating_Model'!G14 -> 0.080338266 | H14: ='06_Operating_Model'!H14 -> 0.078277886 | I14: ='06_Operating_Model'!I14 -> 0.068965517 | J14: ='06_Operating_Model'!J14 -> 0.05942275
A15: Fleet identity check | B15: aircraft | C15: =C13-C9-C12 -> 0 | D15: =D13-D9-D12 -> 0 | E15: =E13-E9-E12 -> 0 | F15: =F13-F9-F12 -> 0 | G15: =G13-G9-G12 -> 0 | H15: =H13-H9-H12 -> 0 | I15: =I13-I9-I12 -> 0 | J15: =J13-J9-J12 -> 0
A17: Lease Liability Schedule
A18: Beginning lease liabilities | B18: INR crore | C18: ='02_Raw_Financials'!J60+'02_Raw_Financials'!J68 -> 42601.876 | D18: =C20 -> 49388.313 | E18: =D20 -> 65009.8 | F18: =E20 -> 75942.9 | G18: =F20 -> 75942.9 | H18: =G20 -> 74803.756 | I18: =H20 -> 73681.7 | J18: =I20 -> 73681.7
A19: Lease liability growth | B19: % | C19: =C20/C18-1 -> 0.15929902 | D19: =D20/D18-1 -> 0.31629926 | E19: =E20/E18-1 -> 0.16817618 | F19: 0 | G19: -0.015 | H19: -0.015 | I19: 0 | J19: 0.01
A20: Closing lease liabilities | B20: INR crore | C20: ='02_Raw_Financials'!K60+'02_Raw_Financials'!K68 -> 49388.313 | D20: ='02_Raw_Financials'!L60+'02_Raw_Financials'!L68 -> 65009.8 | E20: ='02_Raw_Financials'!M60+'02_Raw_Financials'!M68 -> 75942.9 | F20: =E20*(1+F19) -> 75942.9 | G20: =F20*(1+G19) -> 74803.756 | H20: =G20*(1+H19) -> 73681.7 | I20: =H20*(1+I19) -> 73681.7 | J20: =I20*(1+J19) -> 74418.517
A21: Current portion of total leases | B21: % | C21: =C22/C20 -> 0.23335179 | D21: =D22/D20 -> 0.15907602 | E21: =E22/E20 -> 0.15106613 | F21: 0.14 | G21: 0.13 | H21: 0.12 | I21: 0.11 | J21: 0.1
A22: Current lease liabilities | B22: INR crore | C22: ='02_Raw_Financials'!K68 -> 11524.851 | D22: ='02_Raw_Financials'!L68 -> 10341.5 | E22: ='02_Raw_Financials'!M68 -> 11472.4 | F22: =F20*F21 -> 10632.006 | G22: =G20*G21 -> 9724.4883 | H22: =H20*H21 -> 8841.804 | I22: =I20*I21 -> 8104.987 | J22: =J20*J21 -> 7441.8517
A23: Non-current lease liabilities | B23: INR crore | C23: ='02_Raw_Financials'!K60 -> 37863.462 | D23: ='02_Raw_Financials'!L60 -> 54668.3 | E23: ='02_Raw_Financials'!M60 -> 64470.5 | F23: =F20-F22 -> 65310.894 | G23: =G20-G22 -> 65079.268 | H23: =H20-H22 -> 64839.896 | I23: =I20-I22 -> 65576.713 | J23: =J20-J22 -> 66976.665
A24: Lease balance-sheet check | B24: INR crore | C24: =C20-C22-C23 -> 0 | D24: =D20-D22-D23 -> 0 | E24: =E20-E22-E23 -> 0 | F24: =F20-F22-F23 -> 0 | G24: =G20-G22-G23 -> 0 | H24: =H20-H22-H23 -> 0 | I24: =I20-I22-I23 -> 0 | J24: =J20-J22-J23 -> 0
A25: Lease liabilities / ending fleet | B25: INR crore / aircraft | C25: =C20/C13 -> 134.57306 | D25: =D20/D13 -> 149.79217 | E25: =E20/E13 -> 172.20612 | F25: =F20/F13 -> 160.55581 | G25: =G20/G13 -> 146.387 | H25: =H20/H13 -> 133.72359 | I25: =I20/I13 -> 125.09627 | J25: =J20/J13 -> 119.26044
A26: Lease liabilities / ROU assets | B26: x | C26: =C20/C32 -> 1.4440053 | D26: =D20/D32 -> 1.3247327 | E26: =E20/E32 -> 1.4589253 | F26: =F20/F32 -> 1.430319 | G26: =G20/G32 -> 1.394915 | H26: =H20/H32 -> 1.3603874 | I26: =I20/I32 -> 1.3337132 | J26: =J20/J32 -> 1.3206376
A27: Lease liabilities / EBITDAR | B27: x | C27: =C20/'06_Operating_Model'!C73 -> 2.6168583 | D27: =D20/'06_Operating_Model'!D73 -> 2.7970708 | E27: =E20/'06_Operating_Model'!E73 -> 4.8943003 | F27: =F20/'06_Operating_Model'!F73 -> 4.2958394 | G27: =G20/'06_Operating_Model'!G73 -> 3.4940509 | H27: =H20/'06_Operating_Model'!H73 -> 2.9972368 | I27: =I20/'06_Operating_Model'!I73 -> 2.6834067 | J27: =J20/'06_Operating_Model'!J73 -> 2.4916203
A29: ROU and Owned-Asset Schedule
A30: Beginning ROU assets | B30: INR crore | C30: ='02_Raw_Financials'!J34 -> 26536.495 | D30: =C32 -> 34202.308 | E30: =D32 -> 49073.9 | F30: =E32 -> 52054 | G30: =F32 -> 53095.08 | H30: =G32 -> 53626.031 | I30: =H32 -> 54162.291 | J30: =I32 -> 55245.537
A31: ROU asset growth | B31: % | C31: =C32/C30-1 -> 0.28887813 | D31: =D32/D30-1 -> 0.43481253 | E31: =E32/E30-1 -> 0.060726781 | F31: 0.02 | G31: 0.01 | H31: 0.01 | I31: 0.02 | J31: 0.02
A32: Closing ROU assets | B32: INR crore | C32: ='02_Raw_Financials'!K34 -> 34202.308 | D32: ='02_Raw_Financials'!L34 -> 49073.9 | E32: ='02_Raw_Financials'!M34 -> 52054 | F32: =E32*(1+F31) -> 53095.08 | G32: =F32*(1+G31) -> 53626.031 | H32: =G32*(1+H31) -> 54162.291 | I32: =H32*(1+I31) -> 55245.537 | J32: =I32*(1+J31) -> 56350.448
A33: Property, plant and equipment | B33: INR crore | C33: ='02_Raw_Financials'!K33 -> 1902.912 | D33: ='02_Raw_Financials'!L33 -> 2677.9 | E33: ='02_Raw_Financials'!M33 -> 11087.1 | F33: =E33*(1+F34) -> 13082.778 | G33: =F33*(1+G34) -> 15045.195 | H33: =G33*(1+H34) -> 16850.618 | I33: =H33*(1+I34) -> 18535.68 | J33: =I33*(1+J34) -> 20018.534
A34: PPE growth | B34: % | C34: =C33/'02_Raw_Financials'!J33-1 -> 0.71253158 | D34: =D33/C33-1 -> 0.40726424 | E34: =E33/D33-1 -> 3.1402218 | F34: 0.18 | G34: 0.15 | H34: 0.12 | I34: 0.1 | J34: 0.08
A35: Total aviation fixed assets | B35: INR crore | C35: =SUM(C32:C33) -> 36105.22 | D35: =SUM(D32:D33) -> 51751.8 | E35: =SUM(E32:E33) -> 63141.1 | F35: =SUM(F32:F33) -> 66177.858 | G35: =SUM(G32:G33) -> 68671.226 | H35: =SUM(H32:H33) -> 71012.909 | I35: =SUM(I32:I33) -> 73781.217 | J35: =SUM(J32:J33) -> 76368.982
A36: Depreciation and amortisation | B36: INR crore | C36: ='06_Operating_Model'!C67 -> 6425.729 | D36: ='06_Operating_Model'!D67 -> 8680.2 | E36: ='06_Operating_Model'!E67 -> 10808.2 | F36: ='06_Operating_Model'!F67 -> 11515.736 | G36: ='06_Operating_Model'!G67 -> 12961.16 | H36: ='06_Operating_Model'!H67 -> 14624.349 | I36: ='06_Operating_Model'!I67 -> 16292.051 | J36: ='06_Operating_Model'!J67 -> 17990.806
A37: D&A / closing fixed assets | B37: % | C37: =C36/C35 -> 0.1779723 | D37: =D36/D35 -> 0.1677275 | E37: =E36/E35 -> 0.17117535 | F37: =F36/F35 -> 0.17401191 | G37: =G36/G35 -> 0.18874222 | H37: =H36/H35 -> 0.2059393 | I37: =I36/I35 -> 0.22081571 | J37: =J36/J35 -> 0.2355774
A38: ROU growth less fleet growth | B38: % | C38: =C31-C14 -> 0.081641286 | D38: =D31-D14 -> 0.25225122 | E38: =E31-E14 -> 0.044597749 | F38: =F31-F14 -> -0.052562358 | G38: =G31-G14 -> -0.070338266 | H38: =H31-H14 -> -0.068277886 | I38: =I31-I14 -> -0.048965517 | J38: =J31-J14 -> -0.03942275
A40: Reported owned aircraft | B40: aircraft | E40: 36
A41: Net owned aircraft additions | B41: aircraft | F41: 10 | G41: 10 | H41: 12 | I41: 12 | J41: 12
A42: Ending owned aircraft | B42: aircraft | E42: =E40 -> 36 | F42: =E42+F41 -> 46 | G42: =F42+G41 -> 56 | H42: =G42+H41 -> 68 | I42: =H42+I41 -> 80 | J42: =I42+J41 -> 92
A43: Owned aircraft share | B43: % | E43: =E42/E13 -> 0.081632653 | F43: =F42/F13 -> 0.097251586 | G43: =G42/G13 -> 0.10958904 | H43: =H42/H13 -> 0.12341198 | I43: =I42/I13 -> 0.13582343 | J43: =J42/J13 -> 0.1474359
A44: Finance-lease aircraft | B44: aircraft | E44: 53
A45: Owned + finance-lease aircraft | B45: aircraft | E45: =E40+E44 -> 89
...

Sheet 09_Cash_Flow
A1: Unlevered Free Cash Flow
A2: InterGlobe Aviation Limited | INR crore | FY2024A-FY2031E
A3: Cash flow before financing; lease liabilities are treated as debt in the equity bridge.
A5: Metric | B5: Unit | C5: FY2024A | D5: FY2025A | E5: FY2026A | F5: FY2027E | G5: FY2028E | H5: FY2029E | I5: FY2030E | J5: FY2031E
A6: Period | C6: Actual | D6: Actual | E6: Actual | F6: Forecast | G6: Forecast | H6: Forecast | I6: Forecast | J6: Forecast
A8: Unlevered Free Cash Flow
A9: Operating EBIT excluding other income | B9: INR crore | C9: ='07_Income_Statement'!C24-'07_Income_Statement'!C13 -> 9045.387 | D9: ='07_Income_Statement'!D24-'07_Income_Statement'!D13 -> 8256.3 | E9: ='07_Income_Statement'!E24-'07_Income_Statement'!E13 -> -1927.8 | F9: ='07_Income_Statement'!F24-'07_Income_Statement'!F13 -> 256.5591 | G9: ='07_Income_Statement'!G24-'07_Income_Statement'!G13 -> 2155.9694 | H9: ='07_Income_Statement'!H24-'07_Income_Statement'!H13 -> 3394.8503 | I9: ='07_Income_Statement'!I24-'07_Income_Statement'!I13 -> 4285.2104 | J9: ='07_Income_Statement'!J24-'07_Income_Statement'!J13 -> 4924.0117
A10: Normalised tax rate | B10: % | C10: ='07_Income_Statement'!F36 -> 0.252 | D10: ='07_Income_Statement'!F36 -> 0.252 | E10: ='07_Income_Statement'!F36 -> 0.252 | F10: ='07_Income_Statement'!F36 -> 0.252 | G10: ='07_Income_Statement'!F36 -> 0.252 | H10: ='07_Income_Statement'!F36 -> 0.252 | I10: ='07_Income_Statement'!F36 -> 0.252 | J10: ='07_Income_Statement'!F36 -> 0.252
A11: Tax on EBIT | B11: INR crore | C11: =MAX(C9,0)*C10 -> 2279.4375 | D11: =MAX(D9,0)*D10 -> 2080.5876 | E11: =MAX(E9,0)*E10 -> 0 | F11: =MAX(F9,0)*F10 -> 64.652892 | G11: =MAX(G9,0)*G10 -> 543.3043 | H11: =MAX(H9,0)*H10 -> 855.50227 | I11: =MAX(I9,0)*I10 -> 1079.873 | J11: =MAX(J9,0)*J10 -> 1240.851
A12: NOPAT | B12: INR crore | C12: =C9-C11 -> 6765.9495 | D12: =D9-D11 -> 6175.7124 | E12: =E9-E11 -> -1927.8 | F12: =F9-F11 -> 191.9062 | G12: =G9-G11 -> 1612.6651 | H12: =H9-H11 -> 2539.348 | I12: =I9-I11 -> 3205.3374 | J12: =J9-J11 -> 3683.1608
